Workbook

Sheet 00_Huong_dan
A1: Phiếu khảo sát kỹ thuật — Tích hợp dữ liệu PSS qua IBM MQ
A2: Khách hàng: Vietnam Airlines · Nguồn dữ liệu: Amadeus PSS → IBM MQ · Phiên bản 4.0
A4: Phạm vi tài liệu | B4: Thuần kỹ thuật. Các nội dung về hợp đồng, pháp lý, phân công trách nhiệm và quy trình phê duyệt không thuộc phạm vi phiếu này.
A5: Mục tiêu | B5: Lấy một bản sao dữ liệu có nguồn gốc từ hệ thống Amadeus PSS, hiện đang được đưa vào một queue trên IBM MQ, để phục vụ hệ thống xử lý dữ liệu mới.
A6: Ràng buộc 1 | B6: Không đọc phá huỷ trên queue nguồn. Queue đã có consumer DIH đang GET; đọc trực tiếp sẽ tranh mất message của ứng dụng này.
A7: Ràng buộc 2 | B7: Không thay đổi phía Amadeus trong phương án mặc định.
A8: Ràng buộc 3 | B8: Không tạo backpressure ngược lên queue nguồn trong mọi tình huống vận hành của hệ thống đích.
A10: Cách điền
A11: Cột | B11: Hướng dẫn
A12: Mã | B12: Mã câu hỏi. Không sửa. Dùng để tham chiếu giữa các sheet.
A13: Câu hỏi | B13: Nội dung câu hỏi. Không sửa.
A14: Ưu tiên | B14: P0 = chưa có câu trả lời thì chưa thể chốt kiến trúc. P1 = cần trước khi implement. P2 = cần trước khi go-live. Không sửa.
A15: Trạng thái | B15: Chọn từ danh sách: Chưa trả lời / Đã trả lời / Không áp dụng. Sheet 01_Tong_quan tính tiến độ dựa trên cột này.
A16: Trả lời | B16: Ô cần điền. Nền vàng.
A17: Nguồn verify | B17: Ô cần điền. Ghi nguồn xác minh: tên tài liệu và số trang, tên lệnh MQSC đã chạy, hoặc tên file sample. Trả lời theo trí nhớ thì ghi rõ là theo trí nhớ.
A18: Ghi chú | B18: Ô cần điền. Tuỳ chọn.
A20: Ví dụ một dòng đã điền
A21: Mã | B21: Câu hỏi | C21: Ưu tiên | D21: Trạng thái | E21: Trả lời | F21: Nguồn verify | G21: Ghi chú
A22: A1 | B22: Version chính xác của IBM MQ (dspmqver hoặc DISPLAY QMGR VERSION). | C22: P0 | D22: Đã trả lời | E22: IBM MQ 9.3.0.17 LTS, chạy trên RHEL 8.8 | F22: Output dspmqver ngày 12/08/2026, file dspmqver-qm01.txt | G22: STREAMQ khả dụng
A24: Chú giải màu
A25: Ô nền vàng | B25: Ô cần điền
A26: P0 | B26: Chặn thiết kế
A27: P1 | B27: Cần trước khi implement
A28: P2 | B28: Cần trước khi go-live

Sheet 01_Tong_quan
A1: Tổng quan tiến độ khảo sát
A2: Các số liệu dưới đây tự cập nhật theo cột Trạng thái ở từng sheet câu hỏi.
A4: Phần | B4: Nội dung | C4: Tổng số câu | D4: Số P0 | E4: Đã trả lời | F4: Không áp dụng | G4: Còn lại | H4: % hoàn thành
A5: A | B5: Queue manager và hạ tầng MQ | C5: =COUNTIF(A_Ha_tang_MQ!$C$3:$C$200,"P0")+COUNTIF(A_Ha_tang_MQ!$C$3:$C$200,"P1")+COUNTIF(A_Ha_tang_MQ!$C$3:$C$200,"P2") -> 21 | D5: =COUNTIF(A_Ha_tang_MQ!$C$3:$C$200,"P0") -> 12 | E5: =COUNTIF(A_Ha_tang_MQ!$D$3:$D$200,"Đã trả lời") -> 6 | F5: =COUNTIF(A_Ha_tang_MQ!$D$3:$D$200,"Không áp dụng") -> 1 | G5: =C5-E5-F5 -> 14 | H5: =IFERROR((E5+F5)/C5,0) -> 0.33333333
A6: B | B6: Interface và định dạng dữ liệu từ Amadeus PSS | C6: =COUNTIF(B_Interface_Amadeus!$C$3:$C$200,"P0")+COUNTIF(B_Interface_Amadeus!$C$3:$C$200,"P1")+COUNTIF(B_Interface_Amadeus!$C$3:$C$200,"P2") -> 23 | D6: =COUNTIF(B_Interface_Amadeus!$C$3:$C$200,"P0") -> 19 | E6: =COUNTIF(B_Interface_Amadeus!$D$3:$D$200,"Đã trả lời") -> 0 | F6: =COUNTIF(B_Interface_Amadeus!$D$3:$D$200,"Không áp dụng") -> 9 | G6: =C6-E6-F6 -> 14 | H6: =IFERROR((E6+F6)/C6,0) -> 0.39130435
A7: C | B7: DIH: tương tác với MQ, tài liệu kỹ thuật, rà soát consumer khác | C7: =COUNTIF(#REF!,"P0")+COUNTIF(#REF!,"P1")+COUNTIF(#REF!,"P2") -> #REF! | D7: =COUNTIF(#REF!,"P0") -> #REF! | E7: =COUNTIF(#REF!,"Đã trả lời") -> #REF! | F7: =COUNTIF(#REF!,"Không áp dụng") -> #REF! | G7: =C7-E7-F7 -> #REF! | H7: =IFERROR((E7+F7)/C7,0) -> 0
A8: D | B8: Kết nối, bảo mật kỹ thuật và môi trường | C8: =COUNTIF(#REF!,"P0")+COUNTIF(#REF!,"P1")+COUNTIF(#REF!,"P2") -> #REF! | D8: =COUNTIF(#REF!,"P0") -> #REF! | E8: =COUNTIF(#REF!,"Đã trả lời") -> #REF! | F8: =COUNTIF(#REF!,"Không áp dụng") -> #REF! | G8: =C8-E8-F8 -> #REF! | H8: =IFERROR((E8+F8)/C8,0) -> 0
A9: TỔNG | C9: =SUM(C5:C8) -> #REF! | D9: =SUM(D5:D8) -> #REF! | E9: =SUM(E5:E8) -> #REF! | F9: =SUM(F5:F8) -> #REF! | G9: =SUM(G5:G8) -> #REF! | H9: =IFERROR((E9+F9)/C9,0) -> 0
A11: Ghi chú: các công thức đếm trên vùng dòng 3 đến 200 của từng sheet câu hỏi, dựa trên cột Ưu tiên và cột Trạng thái. Nếu chèn thêm dòng câu hỏi vượt quá dòng 200, cần mở rộng vùng tham chiếu tương ứng. Cột 'Còn lại' = Tổng số câu − Đã trả lời − Không áp dụng.

Sheet A_Ha_tang_MQ
A1: Phần A — Queue manager và hạ tầng MQ
A3: Mã | B3: Câu hỏi | C3: Ưu tiên | D3: Trạng thái | E3: Trả lời | F3: Nguồn verify | G3: Ghi chú
A4: A1 | B4: Version chính xác của IBM MQ (dspmqver hoặc DISPLAY QMGR VERSION). | C4: P0 | D4: Đã trả lời | E4: 9.1.2.0
A5: A2 | B5: Platform: z/OS, AIX, Linux, Windows, MQ Appliance, hay container? | C5: P0 | D5: Đã trả lời | E5: Windows
A6: A3 | B6: Mô hình HA: standalone, Multi-Instance QM, RDQM, hay HA cluster của OS? | C6: P0 | D6: Đã trả lời | E6: HA cluster (Windows Server Failover Cluster - WSFC). Hai node IBM MQ Server chạy active/passive; khi một node gặp sự cố, Queue Manager được failover sang node còn lại. Một máy Windows iSCSI được sử dụng làm quorum witness (vote) để duy trì quorum của cluster.
A7: A4 | B7: Tên queue manager, hostname/IP, listener port. Nếu HA thì liệt kê đầy đủ connection name list. | C7: P1 | D7: Chưa trả lời | E7: Queue Manager: VNRD01 Hostname: MQ01-DIH-PROD/10.111.12.2 , MQ02-DIH-PROD/10.111.12.3 Listener port: 6666
A8: A5 | B8: Tên chính xác của queue nguồn. Nó là local queue, alias, remote queue hay cluster queue? | C8: P0 | D8: Chưa trả lời | E8: 1. VN.CMB.PRD.IN - Local queue 2. VN.CMP.PRD.IN - Local queue 3. VN.PNR.PRD.IN - Local queue 4. VN.SKD.PRD.IN - Local queue 5. VN.TKT.PRD.IN - Local queue
A9: A6 | B9: Nếu là cluster queue: có nhiều instance trên nhiều QM không, workload balancing có đang chia message không? | C9: P0 | D9: Không áp dụng
A10: A7 | B10: Hiện đã xác định DIH đang GET từ queue này. Ngoài DIH còn ứng dụng nào khác đang mở queue không? Thực hiện theo giao thức lấy mẫu tại sheet E2_QSTATUS thay vì chụp một lần. | C10: P0 | D10: Đã trả lời | E10: Không có
A11: A8 | B11: Feed PSS này hiện được phân phối cho bao nhiêu hệ thống? Nếu nhiều hơn một, cơ chế fan-out hiện tại là gì: nhiều queue, topic, hay một lớp ESB? | C11: P0 | D11: Đã trả lời | E11: Chỉ 1 hệ thống DIH
A12: A9 | B12: Với version hiện tại, có bật được attribute STREAMQ trên queue nguồn để nhân bản message sang một queue riêng không? (yêu cầu MQ 9.3 trở lên) | C12: P0 | D12: Đã trả lời | E12: Không khả thi do hệ thống đang chạy IBM MQ 9.1.2.0.
A13: A10 | B13: Nếu không dùng được STREAMQ: phương án chuyển queue nguồn thành QALIAS với TARGTYPE(TOPIC) và tạo administrative subscription có khả thi về mặt kỹ thuật không? | C13: P0 | D13: Chưa trả lời | E13: có
A14: A11 | B14: Volume: TPS trung bình, TPS peak, tổng số message/ngày, tổng dung lượng/ngày. | C14: P0 | D14: Chưa trả lời | E14: 1. DCS_BAGGAGE: TPS trung bình - 14, TPS peak - 20, Tổng số message/ngày - 939,987. 2. DCS_PASSENGER: TPS trung bình - 41, TPS peak - 50, Tổng số message/ngày - 2,578,328. 3. PNR: TPS trung bình - 30 records/s, TPS peak - 40 records/s, Tổng số message/ngày - 1755603. 4. SKD: TPS trung bình - 10, TPS peak - 12, Tổng số message/ngày - 668,839. 5. TKT: TPS trung bình - 16, TPS peak - 25, Tổng số message/ngày - 833,890.
A15: A12 | B15: Phân bố theo thời gian: đều trong ngày, hay dồn theo chu kỳ khai thác (giờ bay cao điểm, kỳ chốt cuối tháng)? Queue depth cao nhất từng ghi nhận? | C15: P1 | D15: Chưa trả lời
A16: A13 | B16: Queue attributes hiện tại: MAXDEPTH, MAXMSGL, DEFPSIST, BOTHRESH, BOQNAME, GET/PUT status. | C16: P1 | D16: Chưa trả lời | E16: MAXDEPTH: 10000000 MAXMSGL: 4194304 DEFPSIST: Not persistent BOTHRESH: BOQNAME: GET status: Allowed PUT status: Allowed
A17: A14 | B17: Nếu cấp queue riêng: MAXDEPTH dự kiến là bao nhiêu, tương đương bao nhiêu giờ backlog ở TPS peak? Dung lượng log và storage còn dư có đủ không? | C17: P0 | D17: Chưa trả lời | E17: MAXDEPTH: 10000000 Đủ
A18: A15 | B18: Dead letter queue của QM (DEADQ) là queue nào? Hiện có message tồn trong đó không, và với Reason code nào? | C18: P1 | D18: Chưa trả lời | E18: Không có
A19: A16 | B19: CCSID của queue manager và CCSID được set trên message ở queue nguồn. | C19: P0 | D19: Chưa trả lời
A20: A17 | B20: Kích thước message: trung bình, p99, tối đa. Có message nào vượt MAXMSGL của channel không? | C20: P1 | D20: Chưa trả lời | E20: không rõ
A21: A18 | B21: Channel dùng cho hệ thống mới: SVRCONN riêng hay dùng chung? Giá trị MAXINST, MAXINSTC, SHARECNV, HBINT. | C21: P1 | D21: Chưa trả lời | E21: svrconn
A22: A19 | B22: Có CCDT không? Định dạng binary hay JSON? Cơ chế phân phối tới client (file, MQCCDTURL)? | C22: P1 | D22: Chưa trả lời | E22: không
A23: A20 | B23: Lịch maintenance window và lịch restart QM. Khi QM restart, client có được kỳ vọng tự reconnect không, và SHARECNV hiện tại có cho phép bật MQCNO_RECONNECT không? | C23: P1 | D23: Chưa trả lời | E23: không
A24: A21 | B24: Hệ thống monitoring MQ đang dùng là gì? Có expose được metric queue depth, channel status, và message rate cho hệ thống mới không? | C24: P2 | D24: Chưa trả lời | E24: không

Sheet B_Interface_Amadeus
A1: Phần B — Interface và định dạng dữ liệu từ Amadeus PSS
A2: Phần lớn nội dung dưới đây đã có sẵn trong tài liệu đặc tả interface do Amadeus cung cấp. Đề nghị cung cấp tài liệu thay vì trả lời theo trí nhớ; nội dung sẽ được đối chiếu lại với sample message thực tế.
A4: Mã | B4: Câu hỏi | C4: Ưu tiên | D4: Trạng thái | E4: Trả lời | F4: Nguồn verify | G4: Ghi chú
A5: B1 | B5: Tên chính xác của interface hoặc dịch vụ Amadeus đang cấp dữ liệu cho queue này, kèm số hiệu và phiên bản tài liệu đặc tả. | C5: P0 | D5: Không áp dụng
A6: B2 | B6: Loại dữ liệu nghiệp vụ đi qua feed: đặt chỗ, vé, sự kiện làm thủ tục, lịch bay, tải chỗ, hay hỗn hợp nhiều loại trên cùng một queue? | C6: P0 | D6: Chưa trả lời | E6: mỗi loại 1 queue
A7: B3 | B7: Nếu hỗn hợp nhiều loại: phân biệt loại message bằng cách nào — field trong MQMD, header trong payload, hay MQMD.Format? | C7: P0 | D7: Không áp dụng
A8: B4 | B8: Format payload: message teletype kiểu IATA Type B, EDIFACT theo chuẩn PADIS, XML, JSON, hay fixed-length record? Nếu theo chuẩn ngành thì phiên bản chuẩn nào? | C8: P0 | D8: Chưa trả lời | E8: json
A9: B5 | B9: Amadeus đẩy trực tiếp vào queue này, hay có một thành phần trung gian ở giữa (adapter, ESB, gateway, MQ-to-MQ channel)? Nếu có, thành phần đó biến đổi dữ liệu hay chỉ chuyển tiếp nguyên trạng? | C9: P0 | D9: Chưa trả lời | E9: đẩy trực tiếp
A10: B6 | B10: Thành phần thực hiện PUT set MQMD.Persistence là PERSISTENT hay NON_PERSISTENT? | C10: P0 | D10: Không áp dụng
A11: B7 | B11: Có set MQMD.Expiry không? Giá trị bao nhiêu? (-1 = MQEI_UNLIMITED = không hết hạn; đơn vị là phần mười giây) | C11: P0 | D11: Không áp dụng
A12: B8 | B12: Khi PUT nhận MQRC_2053 (MQRC_Q_FULL), hành vi kỹ thuật là gì: retry, ghi log rồi bỏ qua, hay dừng kênh nhận và tích luỹ ở đầu nguồn? | C12: P0 | D12: Không áp dụng
A13: B9 | B13: Bộ ký tự của payload. Cụ thể: tên hành khách truyền ở dạng chữ in hoa không dấu hay có giữ dấu tiếng Việt? Nếu không dấu, việc lược dấu xảy ra ở Amadeus hay ở thành phần trung gian tại B5? | C13: P0 | D13: Chưa trả lời | E13: không có tiếng việt
A14: B10 | B14: Có trường nào trong payload dùng bộ ký tự khác phần còn lại không (ví dụ trường ghi chú tự do)? | C14: P1 | D14: Chưa trả lời | E14: không
A15: B11 | B15: Phạm vi ordering: thứ tự có ý nghĩa trong phạm vi từng hồ sơ đặt chỗ (theo record locator), hay bắt buộc đúng thứ tự trên toàn bộ feed? | C15: P0 | D15: Chưa trả lời | E15: không rõ
A16: B12 | B16: Nếu theo record locator: field chứa record locator nằm ở MQMD hay trong payload, tên field cụ thể? | C16: P0 | D16: Không áp dụng
A17: B13 | B17: Thứ tự hiện tại có được đảm bảo về mặt kỹ thuật không? Có bao nhiêu kênh truyền song song từ Amadeus, MQMD.Priority có được dùng khác nhau không? | C17: P0 | D17: Không áp dụng
A18: B14 | B18: Message có mang sequence number hoặc timestamp phát sinh tại nguồn không? Nếu có: tên field, và ngữ nghĩa là tăng đơn điệu trên toàn feed hay theo từng hồ sơ? | C18: P0 | D18: Chưa trả lời | E18: có trong tài liệu của amadeus
A19: B15 | B19: Đặc tả có nêu khả năng message trùng lặp không? Có cơ chế retransmission khi đầu nhận không xác nhận không? | C19: P0 | D19: Chưa trả lời | E19: không rõ
A20: B16 | B20: Có cơ chế phát hiện thiếu sót dữ liệu không: sequence liên tục, control total cuối ngày, hay file đối soát? | C20: P0 | D20: Chưa trả lời | E20: có tổng hợp số cuối ngày
A21: B17 | B21: Amadeus có phát lại dữ liệu quá khứ được không? Trong phạm vi bao nhiêu ngày, và dữ liệu phát lại đi vào cùng queue hay một kênh riêng? | C21: P0 | D21: Chưa trả lời | E21: tùy thuộc yêu cầu với amadeus
A22: B18 | B22: Field nào trong payload dùng làm idempotency key ổn định (record locator kết hợp version, hay transaction id do nguồn sinh)? | C22: P0 | D22: Chưa trả lời | E22: event id
A23: B19 | B23: Field nào trong MQMD mang ý nghĩa nghiệp vụ: MsgId, CorrelId, GroupId, MsgSeqNumber, ApplIdentityData, PutApplName, PutDate/PutTime? | C23: P1 | D23: Không áp dụng | E23: không có
A24: B20 | B24: Có dùng message grouping hoặc segmentation không? Message vượt giới hạn kích thước được chia nhiều phần theo cơ chế nào? | C24: P1 | D24: Không áp dụng
A25: B21 | B25: Interface có versioning không? Phiên bản hiện tại đang chạy là gì, và các phiên bản trước có thay đổi format ở mức nào? | C25: P1 | D25: Chưa trả lời | E25: không rõ
A26: B22 | B26: Cung cấp được toàn bộ message thực tế trong một cửa sổ 7 ngày liên tục (đã che dữ liệu nhạy cảm) không? Đề nghị dump cả MQMD và body, giữ nguyên thứ tự nhận, ghi rõ mốc bắt đầu và kết thúc của cửa sổ, và ưu tiên cửa sổ có chứa ngày chốt cuối tháng. Nếu dung lượng lớn, thống nhất trước về định dạng xuất và cách nén. | C26: P0 | D26: Chưa trả lời | E26: chỉ lấy đc msg
A27: B23 | B27: Nếu áp dụng phương án QALIAS → TOPIC (mục A10): đường truyền từ Amadeus tới queue có bị ảnh hưởng không? Cấu hình đầu nguồn có tham chiếu tới tên và loại object đích không? | C27: P0 | D27: Chưa trả lời | E27: không rõ
A29: Về B9: câu hỏi này ảnh hưởng trực tiếp tới chất lượng đối sánh danh tính ở hệ thống đích. Nếu tên hành khách đến ở dạng in hoa không dấu, việc gộp hồ sơ với các nguồn dữ liệu khác có tên đầy đủ dấu cần chiến lược chuẩn hoá riêng và có tỷ lệ nhận nhầm cao hơn, do phân bố họ tên tiếng Việt rất tập trung. Đây là ràng buộc cần biết ở giai đoạn thiết kế, không phải ở giai đoạn tinh chỉnh mô hình.

Sheet C_Consumer
A1: Phần C — Consumer hiện tại (DIH) và rà soát consumer khác
A2: DIH là một mini data warehouse do một nhà cung cấp khác phát triển cho Quý khách. Phạm vi phần này giới hạn ở cách DIH tương tác với queue manager, bộ tài liệu kỹ thuật của DIH, và việc rà soát các consumer khác. Không khảo sát hệ thống downstream của DIH. Với mỗi consumer bổ sung được xác định ở nhóm C.3, tạo một bản sao sheet này và điền lại nhóm C.1.
A4: Consumer đang khảo sát | B4: DIH
A6: Mã | B6: Câu hỏi | C6: Ưu tiên | D6: Trạng thái | E6: Trả lời | F6: Nguồn verify | G6: Ghi chú
A7: C.1 — Cách DIH tương tác với queue manager
A8: C1 | B8: Version DIH đang chạy trên production và ngày triển khai bản hiện tại. | C8: P1 | D8: Đã trả lời | E8: VDP2.0
A9: C2 | B9: DIH kết nối theo kiểu client binding qua SVRCONN hay local binding? Dùng channel nào, và giá trị APPLTAG mà DIH đăng ký là gì? | C9: P0 | D9: Đã trả lời | E9: SVRCONN, channel App
A10: C3 | B10: DIH giữ connection thường trực hay connect/disconnect theo từng phiên xử lý? Chiếm bao nhiêu connection và channel instance ở trạng thái bình thường và lúc peak? | C10: P0 | D10: Đã trả lời | E10: Giữ connection, mỗi queue 1 connection
A11: C4 | B11: DIH mở queue với option nào: MQOO_INPUT_SHARED hay MQOO_INPUT_EXCLUSIVE? Có dùng MQOO_BROWSE trước khi GET không? | C11: P0 | D11: Đã trả lời | E11: MQOO_INPUT_SHARED, không browse trước
A12: C5 | B12: Có bao nhiêu instance DIH chạy song song, và chúng cùng GET trên một queue hay mỗi instance một queue riêng? | C12: P0 | D12: Đã trả lời | E12: mỗi queue 1 instance riêng
A13: C6 | B13: DIH GET tuần tự toàn bộ message, hay dùng selective GET theo MsgId, CorrelId hoặc GroupId? Nếu selective, message không khớp điều kiện có tồn lại trong queue không? | C13: P0 | D13: Đã trả lời | E13: Get tuần tự toàn bộ
A14: C7 | B14: DIH GET trong syncpoint hay ngoài syncpoint? Có tham gia XA transaction không? Thời lượng tối đa của một unit of work là bao lâu? | C14: P0 | D14: Đã trả lời | E14: GET trong syncpoint, không dùng XA, và UoW chỉ kéo dài đến lúc receiver commit sau khi nhận/lưu message
A15: C8 | B15: DIH xử lý message hỏng thế nào: dựa vào BOTHRESH và backout queue, hay để message backout lặp lại trên queue nguồn không giới hạn? | C15: P0 | D15: Đã trả lời | E15: không dựa vào BOTHRESH/backout queue của MQ mà xử lý lỗi ở tầng ứng dụng (retry, log, DLQ/error table), tránh để message backout lặp vô hạn trên queue nguồn
A16: C9 | B16: DIH chạy liên tục hay theo lịch batch? Nếu batch, lịch chạy cụ thể là gì? Tần suất và thời lượng downtime theo kế hoạch? | C16: P1 | D16: Đã trả lời | E16: Chạy liên tục
A17: C10 | B17: Khi DIH dừng hoặc xử lý không kịp, queue depth tăng tới mức nào? Hiện có cảnh báo theo ngưỡng depth không, và có cơ chế xả queue nào đang áp dụng (expiry, purge thủ công)? | C17: P0 | D17: Đã trả lời | E17: Max queue depth: 10000000
A18: C11 | B18: DIH có PUT trở lại queue nào khác trên cùng queue manager không: reply queue, error queue, backout queue, hay queue chuyển tiếp? | C18: P1 | D18: Đã trả lời | E18: Không
A19: C12 | B19: DIH có bật client auto-reconnect không? Giá trị SHARECNV và HBINT trên channel mà DIH dùng là bao nhiêu? | C19: P1 | D19: Đã trả lời | E19: CHANNEL(APP) CHLTYPE(SVRCONN) HBINT(20) SHARECNV(10)
A20: C13 | B20: Nếu áp dụng phương án QALIAS → TOPIC (mục A10): DIH có hardcode tên queue, hay có phụ thuộc vào việc object đích là QLOCAL không? | C20: P0 | D20: Đã trả lời | E20: Không hardcode, không có phụ thuộc vào việc object đích là QLOCAL
A21: C.2 — Tài liệu kỹ thuật của DIH
A22: C14 | B22: Bộ tài liệu kỹ thuật của DIH gồm những tài liệu nào (thiết kế kiến trúc, đặc tả tích hợp, tài liệu vận hành, tài liệu bàn giao)? Phiên bản mới nhất và ngày cập nhật cuối của từng tài liệu. | C22: P0 | D22: Đã trả lời | E22: Đã bàn giao
A23: C15 | B23: Tài liệu đặc tả tích hợp giữa DIH và IBM MQ: tên queue, tên channel, tham số kết nối, cơ chế xử lý lỗi và retry. | C23: P0 | D23: Đã trả lời | E23: Đã bàn giao
A24: C16 | B24: Tài liệu mô tả cách DIH diễn giải payload nhận từ Amadeus: mapping từ field trong message sang cấu trúc dữ liệu nội bộ, và các quy tắc xử lý giá trị đặc biệt. | C24: P0 | D24: Đã trả lời | E24: Đã bàn giao
A25: C17 | B25: Runbook vận hành DIH: quy trình khởi động và dừng, thao tác khi queue tồn đọng, thao tác khi gặp message lỗi. | C25: P1 | D25: Đã trả lời | E25: Đã bàn giao
A26: C18 | B26: Tài liệu có liệt kê các tham số cấu hình MQ của DIH có thể điều chỉnh không: batch size, poll interval, số luồng consume, timeout, wait interval? | C26: P1 | D26: Đã trả lời | E26: Đã bàn giao
A27: C19 | B27: Có nhật ký thay đổi ghi nhận các điều chỉnh cấu hình MQ của DIH kể từ khi triển khai không? | C27: P1 | D27: Đã trả lời | E27: Không thay đổi
A28: C.3 — Rà soát các consumer khác ngoài DIH
A29: C20 | B29: Ngoài DIH, còn ứng dụng nào khác đang GET từ queue nguồn không? Nếu có, liệt kê tên và APPLTAG tương ứng. | C29: P0 | D29: Đã trả lời | E29: Không
A30: C21 | B30: Có công cụ nào chỉ BROWSE queue này mà không GET không, ví dụ công cụ giám sát, đối soát, hay script vận hành? | C30: P0 | D30: Đã trả lời | E30: Không
A31: C22 | B31: Có ứng dụng nào kết nối theo lịch (cuối ngày, cuối tháng, theo sự kiện) mà không thường trực không? Nếu có, lịch kết nối là gì? | C31: P0 | D31: Đã trả lời | E31: Không
A32: C23 | B32: Trong kết quả lấy mẫu QSTATUS tại sheet E2_QSTATUS, có xuất hiện APPLTAG nào ngoài giá trị DIH khai ở mục C2 không? Nếu có, liệt kê kèm OPENOPTS tương ứng. | C32: P0 | D32: Đã trả lời | E32: Chưa chạy được

Sheet D_Ket_noi_Bao_mat
A1: Phần D — Kết nối, bảo mật kỹ thuật và môi trường
A3: Mã | B3: Câu hỏi | C3: Ưu tiên | D3: Trạng thái | E3: Trả lời | F3: Nguồn verify | G3: Ghi chú
A4: D1 | B4: Mô hình kết nối khả thi: (a) kết nối trực tiếp vào queue manager qua SVRCONN từ hạ tầng của hệ thống mới, (b) đặt agent trong mạng nội bộ, hay (c) qua một lớp trung gian sẵn có? | C4: P0 | D4: Đã trả lời | E4: Mạng nội bộ
A5: D2 | B5: Có sẵn lớp integration nào (ACE/IIB, ESB, API gateway) có thể đảm nhiệm việc nhân bản hoặc đẩy dữ liệu không? Nếu có, sản phẩm gì và version nào? | C5: P0 | D5: Đã trả lời | E5: Không
A6: D3 | B6: Queue nguồn có bật AMS (Advanced Message Security) không? Nếu có, policy là sign, encrypt, hay cả hai, và dùng thuật toán nào? | C6: P0 | D6: Đã trả lời | E6: không dùng AMS
A7: D4 | B7: TLS có bắt buộc trên SVRCONN không? SSLCIPH cụ thể, TLS 1.2 hay 1.3? Có yêu cầu mutual TLS không? | C7: P1 | D7: Đã trả lời | E7: hiện không sử dụng TLS (SSLCIPH trống), nên không có TLS 1.2/1.3 và cũng không áp dụng mutual TLS, mặc dù SSLCAUTH(REQUIRED) đã được cấu hình.
A8: D5 | B8: Định dạng keystore mà phía client cần chuẩn bị: JKS, PKCS12, hay kdb? Có ràng buộc SSLPEER trên Distinguished Name không? | C8: P1 | D8: Đã trả lời | E8: Không yêu cầu keystore và không có ràng buộc SSLPEER trên Distinguished Name.
A9: D6 | B9: Ngày hết hạn của certificate đang dùng trên channel liên quan. | C9: P1 | D9: Đã trả lời | E9: N/A
A10: D7 | B10: CONNAUTH đang dùng cơ chế nào: OS user, LDAP, hay IDPWOS? | C10: P1 | D10: Đã trả lời | E10: OS user
A11: D8 | B11: CHLAUTH rules áp lên channel là gì? Có ràng buộc theo địa chỉ nguồn không? | C11: P1 | D11: Đã trả lời | E11: không ràng buộc theo địa chỉ IP nguồn
A12: D9 | B12: Quyền cần có trên MQ để consume: connect và inq trên QM; get, browse, inq trên queue đích. Có ràng buộc kỹ thuật nào khác không? | C12: P1 | D12: Đã trả lời | E12: Không
A13: D10 | B13: Giữa hạ tầng của hệ thống mới và QM có load balancer hoặc firewall có idle timeout không? Giá trị bao nhiêu giây? | C13: P1 | D13: Đã trả lời | E13: không
A14: D11 | B14: Đường mạng: VPN site-to-site, leased line, hay Direct Connect? Băng thông khả dụng? Có NAT trên đường đi không? | C14: P1 | D14: Đã trả lời | E14: không rõ
A15: D12 | B15: Có bao nhiêu environment (DEV/SIT/UAT/PROD)? Feed PSS tồn tại ở env nào? | C15: P0 | D15: Đã trả lời | E15: PROD
... A17: D14 | B17: Nếu môi trường thấp không có feed đại diện: thực hiện BROWSE (không phá huỷ) trên production để xác minh định dạng có khả thi về mặt kỹ thuật không? | C17: P0 | D17: Đã trả lời | E17: N/A

Sheet E1_Artifact
A1: Phần E1 — Artifact và dữ liệu cần cung cấp
A3: # | B3: Artifact | C3: Ghi chú | D3: Trạng thái | E3: Tên file / đường dẫn
A4: 1 | B4: Tài liệu đặc tả interface Amadeus tương ứng với feed này (mục B1) | C4: Artifact quan trọng nhất của đợt khảo sát; toàn bộ bài toán parsing phụ thuộc mục này | D4: Chưa nhận
A5: 2 | B5: Dữ liệu message thực tế trong cửa sổ 7 ngày liên tục, đã che dữ liệu nhạy cảm, dump cả MQMD và body | C5: Giữ nguyên thứ tự nhận; ghi rõ mốc bắt đầu và kết thúc; ưu tiên cửa sổ có chứa ngày chốt cuối tháng | D5: Chưa nhận
A6: 3 | B6: Sơ đồ luồng dữ liệu từ Amadeus tới queue nguồn | C6: Thể hiện mọi thành phần trung gian (mục B5) | D6: Chưa nhận
A7: 4 | B7: Sơ đồ mạng từ hạ tầng hệ thống mới tới queue manager | C7: Ghi rõ mọi hop, load balancer, firewall | D7: Chưa nhận
A8: 5 | B8: CCDT file và hướng dẫn import certificate | C8: Kèm định dạng keystore yêu cầu (mục D5) | D8: Chưa nhận
A9: 6 | B9: Bộ tài liệu kỹ thuật của DIH: thiết kế kiến trúc, đặc tả tích hợp MQ, mapping payload Amadeus, runbook vận hành | C9: Mục C14–C19; tài liệu mapping payload có giá trị đối chiếu cao với đặc tả Amadeus | D9: Chưa nhận
A10: 7 | B10: Output MQSC theo danh sách tại sheet E3_MQSC | C10: Chạy trên queue manager production | D10: Chưa nhận
A11: 8 | B11: Log lấy mẫu QSTATUS theo giao thức tại sheet E2_QSTATUS | C11: Tối thiểu 2 tuần, bao gồm một kỳ chốt cuối tháng | D11: Chưa nhận

Sheet E2_QSTATUS
A1: Phần E2 — Giao thức lấy mẫu để xác định consumer
A3: DISPLAY QSTATUS ... TYPE(HANDLE) chỉ hiển thị các connection đang mở tại thời điểm chạy. Consumer dạng batch chỉ kết nối khi job chạy — thường ban đêm hoặc kỳ chốt tháng — và sẽ vô hình nếu chỉ chụp một lần trong giờ hành chính. Với một feed PSS phục vụ nhiều hệ thống, bỏ sót một consumer dẫn tới mất dữ liệu rải rác ở hệ thống đó, và thường chỉ phát hiện khi đối soát cuối kỳ.
A5: Đề nghị chạy định kỳ mỗi 30 phút, trong tối thiểu hai tuần, bao gồm một kỳ chốt cuối tháng:
A7: #!/bin/sh
A8: # Ghi nhận các handle đang mở trên queue nguồn. Đặt lịch chạy mỗi 30 phút qua cron.
A9: QM=<tên queue manager>
A10: Q=<tên queue nguồn>
A11: OUTDIR=/var/log/mqsurvey
A12: mkdir -p "$OUTDIR"
A13: OUT="$OUTDIR/qstatus-$(date +%Y%m%d-%H%M%S).log"
A14: {
A15: echo "DISPLAY QSTATUS($Q) TYPE(HANDLE) ALL"
... A21: Nếu không đặt lịch được, tối thiểu chụp tại các mốc: giờ hành chính, đêm khuya, rạng sáng, ngày làm việc đầu tháng, và ngày chốt cuối tháng.

Sheet E3_MQSC
A1: Phần E3 — MQSC command output cần cung cấp
A3: Lệnh | B3: Trạng thái | C3: Tên file output
A4: DISPLAY QMGR ALL | B4: Đã chạy | C4: DISPLAY QMGR ALL 8 : DISPLAY QMGR ALL AMQ8408I: Display Queue Manager details. QMNAME(VNRD01) ACCTCONO(DISABLED) ACCTINT(1800) ACCTMQI(OFF) ACCTQ(OFF) ACTIVREC(MSG) ACTVCONO(DISABLED) ACTVTRC(OFF) ADVCAP(DISABLED) ALTDATE(2026-03-16) ALTTIME(17.03.47) AMQPCAP(NO) AUTHOREV(DISABLED) CCSID(437) CERTLABL(ibmwebspheremqvnrd01) CERTVPOL(ANY) CHAD(DISABLED) CHADEV(DISABLED) CHADEXIT( ) CHLEV(DISABLED) CHLAUTH(ENABLED) CLWLDATA( ) CLWLEXIT( ) CLWLLEN(100) CLWLMRUC(999999999) CLWLUSEQ(LOCAL) CMDEV(DISABLED) CMDLEVEL(912) COMMANDQ(SYSTEM.ADMIN.COMMAND.QUEUE) CONFIGEV(DISABLED) CONNAUTH(SYSTEM.DEFAULT.AUTHINFO.IDPWOS) CRDATE(2026-03-16) CRTIME(17.03.47) CUSTOM( ) DEADQ( ) DEFCLXQ(SCTQ) DEFXMITQ( ) DESCR( ) DISTL(YES) IMGINTVL(60) IMGLOGLN(OFF) IMGRCOVO(YES) IMGRCOVQ(YES) IMGSCHED(MANUAL) INHIBTEV(DISABLED) IPADDRV(IPV4) LOCALEV(DISABLED) LOGGEREV(DISABLED) MARKINT(5000) MAXHANDS(256) MAXMSGL(4194304) MAXPROPL(NOLIMIT) MAXPRTY(9) MAXUMSGS(10000) MONACLS(QMGR) MONCHL(OFF) MONQ(OFF) PARENT( ) PERFMEV(DISABLED) PLATFORM(WINDOWSNT) PSMODE(ENABLED) PSCLUS(ENABLED) PSNPMSG(DISCARD) PSNPRES(NORMAL) PSRTYCNT(5) PSSYNCPT(IFPER) QMID(VNRD01_2026-03-16_17.03.47) REMOTEEV(DISABLED) REPOS( ) REPOSNL( ) REVDNS(ENABLED) ROUTEREC(MSG) SCHINIT(QMGR) SCMDSERV(QMGR) SPLCAP(DISABLED) SSLCRLNL( ) SSLCRYP( ) SSLEV(DISABLED) SSLFIPS(NO) SSLKEYR(C:\ProgramData\IBM\MQ\qmgrs\VNRD01\ssl\key) SSLRKEYC(0) STATACLS(QMGR) STATCHL(OFF) STATINT(1800) STATMQI(OFF) STATQ(OFF) STRSTPEV(ENABLED) SUITEB(NONE) SYNCPT TREELIFE(1800) TRIGINT(999999999) VERSION(09010200) XRCAP(NO)
A5: DISPLAY QLOCAL(<tên queue nguồn>) ALL | B5: Đã chạy | C5: DISPLAY QLOCAL(VN.CMB.PRD.IN) ALL 9 : DISPLAY QLOCAL(VN.CMB.PRD.IN) ALL AMQ8409I: Display Queue details. QUEUE(VN.CMB.PRD.IN) TYPE(QLOCAL) ACCTQ(QMGR) ALTDATE(2026-07-24) ALTTIME(11.19.26) BOQNAME( ) BOTHRESH(0) CLUSNL( ) CLUSTER( ) CLCHNAME( ) CLWLPRTY(0) CLWLRANK(0) CLWLUSEQ(QMGR) CRDATE(2026-03-16) CRTIME(17.05.48) CURDEPTH(0) CUSTOM( ) DEFBIND(OPEN) DEFPRTY(0) DEFPSIST(NO) DEFPRESP(SYNC) DEFREADA(NO) DEFSOPT(SHARED) DEFTYPE(PREDEFINED) DESCR( ) DISTL(NO) GET(ENABLED) HARDENBO IMGRCOVQ(QMGR) INITQ( ) IPPROCS(1) MAXDEPTH(10000000) MAXMSGL(4194304) MONQ(QMGR) MSGDLVSQ(PRIORITY) NOTRIGGER NPMCLASS(NORMAL) OPPROCS(0) PROCESS( ) PUT(ENABLED) PROPCTL(COMPAT) QDEPTHHI(80) QDEPTHLO(20) QDPHIEV(DISABLED) QDPLOEV(DISABLED) QDPMAXEV(ENABLED) QSVCIEV(NONE) QSVCINT(999999999) RETINTVL(999999999) SCOPE(QMGR) SHARE STATQ(QMGR) TRIGDATA( ) TRIGDPTH(1) TRIGMPRI(0) TRIGTYPE(FIRST) USAGE(NORMAL)
A6: DISPLAY QUEUE(<tên queue nguồn>) TYPE(ALL) | B6: Đã chạy | C6: DISPLAY QLOCAL(VN.CMB.PRD.IN) TYPE(ALL) 10 : DISPLAY QLOCAL(VN.CMB.PRD.IN) TYPE(ALL) AMQ8428I: TYPE Keyword has already been specified. DISPLAY QLOCAL(VN.CMB.PRD.IN) TYPE(ALL) AMQ8427I: Valid syntax for the MQSC command: DISPLAY QLOCAL( generic_q_name ) [ WHERE( filter_keyword operator filter_value ) ] [ CLUSTER( generic_cluster_name ) ] [ CLUSNL( generic_namelist_name ) ] [ ALL ] [ ACCTQ ] [ ALTDATE ] [ ALTTIME ] [ BOQNAME ] [ BOTHRESH ] [ CLCHNAME ] [ CLUSDATE ] [ CLUSINFO ] [ CLUSNL ] [ CLUSQMGR ] [ CLUSQT ] [ CLUSTER ] [ CLUSTIME ] [ CLWLPRTY ] [ CLWLRANK ] [ CLWLUSEQ ] [ CRDATE ] [ CRTIME ] [ CURDEPTH ] [ CUSTOM ] [ DEFBIND ] [ DEFPRESP ] [ DEFPRTY ] [ DEFPSIST ] [ DEFREADA ] [ DEFSOPT ] [ DEFTYPE ] [ DESCR ] [ DISTL ] [ GET ] [ HARDENBO ] [ INITQ ] [ IMGRCOVQ ] [ IPPROCS ] [ MAXDEPTH ] [ MAXMSGL ] [ MONQ ] [ MSGDLVSQ ] [ NPMCLASS ] [ OPPROCS ] [ PROCESS ] [ PROPCTL ] [ PUT ] [ QDEPTHHI ] [ QDEPTHLO ] [ QDPHIEV ] [ QDPLOEV ] [ QDPMAXEV ] [ QMID ] [ QSVCIEV ] [ QSVCINT ] [ QTYPE ] [ RETINTVL ] [ SCOPE ] [ SHARE ] [ STATQ ] [ TRIGDATA ] [ TRIGDPTH ] [ TRIGGER ] [ TRIGMPRI ] [ TRIGTYPE ] [ TYPE ] [ USAGE ]
A7: DISPLAY CONN(*) TYPE(ALL) ALL | B7: Đã chạy | C7: DISPLAY CONN(*) TYPE(ALL) ALL 11 : DISPLAY CONN(*) TYPE(ALL) ALL AMQ8276I: Display Connection details. CONN(CCE5626A01F11423) EXTCONN(414D5143564E52443031202020202020) TYPE(*) PID(7276) TID(9) APPLDESC(IBM MQ Distributed Pub/Sub Publish Task) APPLTAG(es\IBM\MQ\bin64\amqzmuf0.exe) APPLTYPE(SYSTEM) ASTATE(NONE) CHANNEL( ) CLIENTID( ) CONNAME( ) CONNOPTS(MQCNO_FASTPATH_BINDING) USERID(prodMqTdh) UOWLOG( ) UOWSTDA(2026-07-24) UOWSTTI(11.10.52) UOWLOGDA( ) UOWLOGTI( ) URTYPE(QMGR) EXTURID(XA_FORMATID[] XA_GTRID[] XA_BQUAL[]) QMURID(0.12289) UOWSTATE(ACTIVE) OBJNAME(SYSTEM.INTER.QMGR.PUBS) OBJTYPE(QUEUE) ASTATE(NONE) HSTATE(ACTIVE) OPENOPTS(MQOO_INPUT_SHARED,MQOO_SAVE_ALL_CONTEXT,MQOO_FAIL_IF_QUIESCING) READA(NO) AMQ8276I: Display Connection details. CONN(CCE5626A01F21423) EXTCONN(414D5143564E52443031202020202020) TYPE(*) PID(7276) TID(7) APPLDESC(IBM MQ Distributed Pub/Sub Fan Out Task) APPLTAG(es\IBM\MQ\bin64\amqzmuf0.exe) APPLTYPE(SYSTEM) ASTATE(NONE) CHANNEL( ) CLIENTID( ) CONNAME( ) CONNOPTS(MQCNO_FASTPATH_BINDING) USERID(prodMqTdh) UOWLOG( ) UOWSTDA(2026-07-24) UOWSTTI(11.10.52) UOWLOGDA( ) UOWLOGTI( ) URTYPE(QMGR) EXTURID(XA_FORMATID[] XA_GTRID[] XA_BQUAL[]) QMURID(0.16385) UOWSTATE(ACTIVE) OBJNAME(SYSTEM.INTER.QMGR.FANREQ) OBJTYPE(QUEUE) ASTATE(NONE) HSTATE(ACTIVE) OPENOPTS(MQOO_INPUT_SHARED,MQOO_OUTPUT,MQOO_SAVE_ALL_CONTEXT,MQOO_FAIL_IF_QUIESCING) READA(NO) AMQ8276I: Display Connection details. CONN(CCE5626A01F31423) EXTCONN(414D5143564E52443031202020202020) TYPE(*) PID(7420) TID(1) APPLDESC(IBM MQ Queued Pub/Sub Controller) APPLTAG(es\IBM\MQ\bin64\amqfqpub.exe) APPLTYPE(SYSTEM) ASTATE(NONE) CHANNEL( ) CLIENTID( ) CONNAME( ) CONNOPTS(MQCNO_FASTPATH_BINDING) USERID(prodMqTdh) UOWLOG( ) UOWSTDA( ) UOWSTTI( ) UOWLOGDA( ) UOWLOGTI( ) URTYPE(QMGR) EXTURID(XA_FORMATID[] XA_GTRID[] XA_BQUAL[]) QMURID(0.0) UOWSTATE(NONE) OBJNAME(VNRD01) OBJTYPE(QMGR) ASTATE(NONE) HSTATE(INACTIVE) OPENOPTS(MQOO_INQUIRE) READA(NO) OBJNAME(SYSTEM.BROKER.ADMIN.STREAM) OBJTYPE(QUEUE) ASTATE(NONE) HSTATE(INACTIVE) OPENOPTS(MQOO_OUTPUT,MQOO_SET_ALL_CONTEXT) READA(NO) AMQ8276I: Display Connection details. CONN(CCE5626A01F41423) EXTCONN(414D5143564E52443031202020202020) TYPE(*) PID(7420) TID(3) APPLDESC(IBM MQ Queued Pub/Sub Controller) APPLTAG(es\IBM\MQ\bin64\amqfqpub.exe) APPLTYPE(SYSTEM) ASTATE(NONE) CHANNEL( ) CLIENTID( ) CONNAME( ) CONNOPTS(MQCNO_FASTPATH_BINDING) USERID(prodMqTdh) UOWLOG( ) UOWSTDA( ) UOWSTTI( ) UOWLOGDA( ) UOWLOGTI( ) URTYPE(QMGR) EXTURID(XA_FORMATID[] XA_GTRID[] XA_BQUAL[]) QMURID(0.0) UOWSTATE(NONE) OBJNAME(SYSTEM.QPUBSUB.QUEUE.NAMELIST) OBJTYPE(NAMELIST) ASTATE(NONE) HSTATE(INACTIVE) OPENOPTS(MQOO_INQUIRE) READA(NO) AMQ8276I: Display Connection details. CONN(CCE5626A01F61423) EXTCONN(414D5143564E52443031202020202020) TYPE(*) PID(7420) TID(4) APPLDESC(IBM MQ Queued Pub/Sub Controller) APPLTAG(es\IBM\MQ\bin64\amqfqpub.exe) APPLTYPE(SYSTEM) ASTATE(NONE) CHANNEL( ) CLIENTID( ) CONNAME( ) CONNOPTS(MQCNO_FASTPATH_BINDING) USERID(prodMqTdh) UOWLOG( ) UOWSTDA(2026-07-24) UOWSTTI(11.10.52) UOWLOGDA( ) UOWLOGTI( ) URTYPE(QMGR) EXTURID(XA_FORMATID[] XA_GTRID[] XA_BQUAL[]) QMURID(0.12312) UOWSTATE(ACTIVE) OBJNAME(SYSTEM.BROKER.INTER.BROKER.COMMUNICATIONS) OBJTYPE(QUEUE) ASTATE(NONE) HSTATE(ACTIVE) OPENOPTS(MQOO_INPUT_EXCLUSIVE) READA(NO) AMQ8276I: Display Connection details. CONN(CCE5626A01F71423) EXTCONN(414D5143564E52443031202020202020) TYPE(*) PID(7440) TID(1) APPLDESC(IBM MQ Channel Initiator) APPLTAG(es\IBM\MQ\bin64\runmqchi.exe) APPLTYPE(CHINIT) ASTATE(STARTED) CHANNEL( ) CLIENTID( ) CONNAME( ) CONNOPTS(MQCNO_HANDLE_SHARE_BLOCK,MQCNO_SHARED_BINDING) USERID(prodMqTdh) UOWLOG( ) UOWSTDA( ) UOWSTTI( ) UOWLOGDA( ) UOWLOGTI( ) URTYPE(QMGR) EXTURID(XA_FORMATID[] XA_GTRID[] XA_BQUAL[]) QMURID(0.0) UOWSTATE(NONE) OBJNAME(SYSTEM.CHANNEL.INITQ) OBJTYPE(QUEUE) ASTATE(ACTIVE) HSTATE(ACTIVE) OPENOPTS(MQOO_INPUT_EXCLUSIVE,MQOO_SET,MQOO_FAIL_IF_QUIESCING) READA(NO) AMQ8276I: Display Connection details. CONN(CCE5626A01F91423) EXTCONN(414D5143564E52443031202020202020) TYPE(*) PID(5600) TID(10) APPLDESC(IBM MQ Deferred Message Processor) APPLTAG(es\IBM\MQ\bin64\amqzmur0.exe) APPLTYPE(SYSTEM) ASTATE(NONE) CHANNEL( ) CLIENTID( ) CONNAME( ) CONNOPTS(MQCNO_SHARED_BINDING) USERID(prodMqTdh) UOWLOG( ) UOWSTDA( ) UOWSTTI( ) UOWLOGDA( ) UOWLOGTI( ) URTYPE(QMGR) EXTURID(XA_FORMATID[] XA_GTRID[] XA_BQUAL[]) QMURID(0.0) UOWSTATE(NONE) OBJNAME(SYSTEM.PENDING.DATA.QUEUE) OBJTYPE(QUEUE) ASTATE(NONE) HSTATE(INACTIVE) OPENOPTS(MQOO_INPUT_EXCLUSIVE,MQOO_BROWSE,MQOO_OUTPUT,MQOO_INQUIRE) READA(NO) AMQ8276I: Display Connection details. CONN(CCE5626A01FB1423) EXTCONN(414D5143564E52443031202020202020) TYPE(*) PID(7484) TID(1) APPLDESC(IBM MQ Command Server) APPLTAG(es\IBM\MQ\bin64\amqpcsea.exe) APPLTYPE(SYSTEM) ASTATE(NONE) CHANNEL( ) CLIENTID( ) CONNAME( ) CONNOPTS(MQCNO_SHARED_BINDING) USERID(prodMqTdh) UOWLOG( ) UOWSTDA( ) UOWSTTI( ) UOWLOGDA( ) UOWLOGTI( ) URTYPE(QMGR) EXTURID(XA_FORMATID[] XA_GTRID[] XA_BQUAL[]) QMURID(0.0) UOWSTATE(NONE) OBJNAME(SYSTEM.ADMIN.COMMAND.QUEUE) OBJTYPE(QUEUE) ASTATE(NONE) HSTATE(ACTIVE) OPENOPTS(MQOO_INPUT_EXCLUSIVE,MQOO_INQUIRE,MQOO_SAVE_ALL_CONTEXT) READA(NO) AMQ8276I: Display Connection details. CONN(CCE5626A01FD1423) EXTCONN(414D5143564E52443031202020202020) TYPE(*) PID(5600) TID(9) APPLDESC(IBM MQ Delayed Delivery Processor) APPLTAG(es\IBM\MQ\bin64\amqzmur0.exe) APPLTYPE(SYSTEM) ASTATE(NONE) CHANNEL( ) CLIENTID( ) CONNAME( ) CONNOPTS(MQCNO_SHARED_BINDING) USERID(prodMqTdh) UOWLOG( ) UOWSTDA( ) UOWSTTI( ) UOWLOGDA( ) UOWLOGTI( ) URTYPE(QMGR) EXTURID(XA_FORMATID[] XA_GTRID[] XA_BQUAL[]) QMURID(0.0) UOWSTATE(NONE) OBJNAME(SYSTEM.DDELAY.LOCAL.QUEUE) OBJTYPE(QUEUE) ASTATE(NONE) HSTATE(ACTIVE) OPENOPTS(MQOO_BROWSE) READA(NO) OBJNAME(SYSTEM.DDELAY.LOCAL.QUEUE) OBJTYPE(QUEUE) ASTATE(NONE) HSTATE(INACTIVE) OPENOPTS(MQOO_INPUT_EXCLUSIVE) READA(NO) AMQ8276I: Display Connection details. CONN(CCE5626A01FE1423) EXTCONN(414D5143564E52443031202020202020) TYPE(*) PID(7568) TID(1) APPLDESC(IBM MQ Queued Pub/Sub Worker) APPLTAG(es\IBM\MQ\bin64\amqfcxba.exe) APPLTYPE(SYSTEM) ASTATE(NONE) CHANNEL( ) CLIENTID( ) CONNAME( ) CONNOPTS(MQCNO_FASTPATH_BINDING) USERID(prodMqTdh) UOWLOG( ) UOWSTDA( ) UOWSTTI( ) UOWLOGDA( ) UOWLOGTI( ) URTYPE(QMGR) EXTURID(XA_FORMATID[] XA_GTRID[] XA_BQUAL[]) QMURID(0.0) UOWSTATE(NONE) AMQ8276I: Display Connection details. CONN(CCE5626A01FF1423) EXTCONN(414D5143564E52443031202020202020) TYPE(*) PID(7568) TID(3) APPLDESC(IBM MQ Queued Pub/Sub Worker) APPLTAG(es\IBM\MQ\bin64\amqfcxba.exe) APPLTYPE(SYSTEM) ASTATE(NONE) CHANNEL( ) CLIENTID( ) CONNAME( ) CONNOPTS(MQCNO_FASTPATH_BINDING) USERID(prodMqTdh) UOWLOG( ) UOWSTDA( ) UOWSTTI( ) UOWLOGDA( ) UOWLOGTI( ) URTYPE(QMGR) EXTURID(XA_FORMATID[] XA_GTRID[] XA_BQUAL[]) QMURID(0.0) UOWSTATE(NONE) OBJNAME(SYSTEM.BROKER.CONTROL.QUEUE) OBJTYPE(QUEUE) ASTATE(NONE) HSTATE(ACTIVE) OPENOPTS(MQOO_BROWSE,MQOO_FAIL_IF_QUIESCING) READA(NO) AMQ8276I: Display Connection details. CONN(CCE5626A01001523) EXTCONN(414D5143564E52443031202020202020) TYPE(*) PID(7568) TID(6) APPLDESC(IBM MQ Queued Pub/Sub Worker) APPLTAG(es\IBM\MQ\bin64\amqfcxba.exe) APPLTYPE(SYSTEM) ASTATE(NONE) CHANNEL( ) CLIENTID( ) CONNAME( ) CONNOPTS(MQCNO_FASTPATH_BINDING) USERID(prodMqTdh) UOWLOG( ) UOWSTDA( ) UOWSTTI( ) UOWLOGDA( ) UOWLOGTI( ) URTYPE(QMGR) EXTURID(XA_FORMATID[] XA_GTRID[] XA_BQUAL[]) QMURID(0.0) UOWSTATE(NONE) OBJNAME(SYSTEM.BROKER.CONTROL.QUEUE) OBJTYPE(QUEUE) ASTATE(NONE) HSTATE(INACTIVE) OPENOPTS(MQOO_INPUT_SHARED,MQOO_FAIL_IF_QUIESCING) READA(NO) AMQ8276I: Display Connection details. CONN(CCE5626A0101D623) EXTCONN(414D5143564E52443031202020202020) TYPE(*) PID(14840) TID(1) APPLDESC(IBM MQ Script Command Processor) APPLTAG(les\IBM\MQ\bin64\runmqsc.exe) APPLTYPE(SYSTEM) ASTATE(STOPPED) CHANNEL( ) CLIENTID( ) CONNAME( ) CONNOPTS(MQCNO_SHARED_BINDING) USERID(Administrato) UOWLOG( ) UOWSTDA( ) UOWSTTI( ) UOWLOGDA( ) UOWLOGTI( ) URTYPE(QMGR) EXTURID(XA_FORMATID[] XA_GTRID[] XA_BQUAL[]) QMURID(0.0) UOWSTATE(NONE) AMQ8276I: Display Connection details. CONN(CCE5626A01011523) EXTCONN(414D5143564E52443031202020202020) TYPE(*) PID(7568) TID(4) APPLDESC(IBM MQ Queued Pub/Sub Worker) APPLTAG(es\IBM\MQ\bin64\amqfcxba.exe) APPLTYPE(SYSTEM) ASTATE(NONE) CHANNEL( ) CLIENTID( ) CONNAME( ) CONNOPTS(MQCNO_FASTPATH_BINDING) USERID(prodMqTdh) UOWLOG( ) UOWSTDA( ) UOWSTTI( ) UOWLOGDA( ) UOWLOGTI( ) URTYPE(QMGR) EXTURID(XA_FORMATID[] XA_GTRID[] XA_BQUAL[]) QMURID(0.0) UOWSTATE(NONE) OBJNAME(SYSTEM.BROKER.CONTROL.QUEUE) OBJTYPE(QUEUE) ASTATE(NONE) HSTATE(INACTIVE) OPENOPTS(MQOO_INPUT_SHARED,MQOO_FAIL_IF_QUIESCING) READA(NO) AMQ8276I: Display Connection details. CONN(CCE5626A01021523) EXTCONN(414D5143564E52443031202020202020) TYPE(*) PID(7568) TID(5) APPLDESC(IBM MQ Queued Pub/Sub Worker) APPLTAG(es\IBM\MQ\bin64\amqfcxba.exe) APPLTYPE(SYSTEM) ASTATE(NONE) CHANNEL( ) CLIENTID( ) CONNAME( ) CONNOPTS(MQCNO_FASTPATH_BINDING) USERID(prodMqTdh) UOWLOG( ) UOWSTDA( ) UOWSTTI( ) UOWLOGDA( ) UOWLOGTI( ) URTYPE(QMGR) EXTURID(XA_FORMATID[] XA_GTRID[] XA_BQUAL[]) QMURID(0.0) UOWSTATE(NONE) OBJNAME(SYSTEM.BROKER.CONTROL.QUEUE) OBJTYPE(QUEUE) ASTATE(NONE) HSTATE(INACTIVE) OPENOPTS(MQOO_INPUT_SHARED,MQOO_FAIL_IF_QUIESCING) READA(NO) AMQ8276I: Display Connection details. CONN(CCE5626A01E21423) EXTCONN(414D5143564E52443031202020202020) TYPE(*) PID(7088) TID(1) APPLDESC(IBM MQ Object Authority Manager) APPLTAG(es\IBM\MQ\bin64\amqzfuma.exe) APPLTYPE(SYSTEM) ASTATE(NONE) CHANNEL( ) CLIENTID( ) CONNAME( ) CONNOPTS(MQCNO_FASTPATH_BINDING) USERID(prodMqTdh) UOWLOG( ) UOWSTDA( ) UOWSTTI( ) UOWLOGDA( ) UOWLOGTI( ) URTYPE(QMGR) EXTURID(XA_FORMATID[] XA_GTRID[] XA_BQUAL[]) QMURID(0.0) UOWSTATE(NONE) OBJNAME(SYSTEM.AUTH.DATA.QUEUE) OBJTYPE(QUEUE) ASTATE(NONE) HSTATE(INACTIVE) OPENOPTS(MQOO_INPUT_EXCLUSIVE,MQOO_BROWSE,MQOO_OUTPUT,MQOO_SET,MQOO_FAIL_IF_QUIESCING) READA(NO) AMQ8276I: Display Connection details. CONN(CCE5626A01031523) EXTCONN(414D5143564E52443031202020202020) TYPE(*) PID(7568) TID(7) APPLDESC(IBM MQ Queued Pub/Sub Worker) APPLTAG(es\IBM\MQ\bin64\amqfcxba.exe) APPLTYPE(SYSTEM) ASTATE(NONE) CHANNEL( ) CLIENTID( ) CONNAME( ) CONNOPTS(MQCNO_FASTPATH_BINDING) USERID(prodMqTdh) UOWLOG( ) UOWSTDA(2026-07-24) UOWSTTI(11.10.52) UOWLOGDA( ) UOWLOGTI( ) URTYPE(QMGR) EXTURID(XA_FORMATID[] XA_GTRID[] XA_BQUAL[]) QMURID(0.12316) UOWSTATE(ACTIVE) OBJNAME(SYSTEM.BROKER.ADMIN.STREAM) OBJTYPE(QUEUE) ASTATE(NONE) HSTATE(ACTIVE) OPENOPTS(MQOO_INPUT_SHARED,MQOO_SAVE_ALL_CONTEXT) READA(NO) AMQ8276I: Display Connection details. CONN(CCE5626A01E31423) EXTCONN(414D5143564E52443031202020202020) TYPE(*) PID(7312) TID(1) APPLDESC(IBM MQ Cluster Repository) APPLTAG(es\IBM\MQ\bin64\amqrrmfa.exe) APPLTYPE(SYSTEM) ASTATE(NONE) CHANNEL( ) CLIENTID( ) CONNAME( ) CONNOPTS(MQCNO_FASTPATH_BINDING) USERID(prodMqTdh) UOWLOG( ) UOWSTDA(2026-07-24) UOWSTTI(11.10.52) UOWLOGDA( ) UOWLOGTI( ) URTYPE(QMGR) EXTURID(XA_FORMATID[] XA_GTRID[] XA_BQUAL[]) QMURID(0.4097) UOWSTATE(ACTIVE) OBJNAME(SYSTEM.CLUSTER.COMMAND.QUEUE) OBJTYPE(QUEUE) ASTATE(NONE) HSTATE(ACTIVE) OPENOPTS(MQOO_INPUT_EXCLUSIVE,MQOO_INQUIRE,MQOO_SET) READA(NO) OBJNAME(SYSTEM.CLUSTER.REPOSITORY.QUEUE) OBJTYPE(QUEUE) ASTATE(NONE) HSTATE(INACTIVE) OPENOPTS(MQOO_INPUT_EXCLUSIVE,MQOO_BROWSE,MQOO_OUTPUT) READA(NO) AMQ8276I: Display Connection details. CONN(CCE5626A01041523) EXTCONN(414D5143564E52443031202020202020) TYPE(*) PID(7568) TID(8) APPLDESC(IBM MQ Queued Pub/Sub Worker) APPLTAG(es\IBM\MQ\bin64\amqfcxba.exe) APPLTYPE(SYSTEM) ASTATE(NONE) CHANNEL( ) CLIENTID( ) CONNAME( ) CONNOPTS(MQCNO_FASTPATH_BINDING) USERID(prodMqTdh) UOWLOG( ) UOWSTDA(2026-07-24) UOWSTTI(11.10.52) UOWLOGDA( ) UOWLOGTI( ) URTYPE(QMGR) EXTURID(XA_FORMATID[] XA_GTRID[] XA_BQUAL[]) QMURID(0.16386) UOWSTATE(ACTIVE) OBJNAME(SYSTEM.BROKER.DEFAULT.STREAM) OBJTYPE(QUEUE) ASTATE(NONE) HSTATE(ACTIVE) OPENOPTS(MQOO_INPUT_SHARED,MQOO_SAVE_ALL_CONTEXT) READA(NO) AMQ8276I: Display Connection details. CONN(CCE5626A01061523) EXTCONN(414D5143564E52443031202020202020) TYPE(*) PID(12304) TID(5) APPLDESC( ) APPLTAG(IBM MQ Client for Java) APPLTYPE(USER) ASTATE(NONE) CHANNEL( ) CLIENTID( ) CONNAME( ) CONNOPTS(MQCNO_HANDLE_SHARE_BLOCK,MQCNO_ISOLATED_BINDING) USERID(Administrato) UOWLOG( ) UOWSTDA( ) UOWSTTI( ) UOWLOGDA( ) UOWLOGTI( ) URTYPE(QMGR) EXTURID(XA_FORMATID[] XA_GTRID[] XA_BQUAL[]) QMURID(0.0) UOWSTATE(NONE) OBJNAME(VNRD01) OBJTYPE(QMGR) ASTATE(NONE) HSTATE(INACTIVE) OPENOPTS(MQOO_INQUIRE) READA(NO) OBJNAME(SYSTEM.ADMIN.COMMAND.QUEUE) OBJTYPE(QUEUE) ASTATE(NONE) HSTATE(INACTIVE) OPENOPTS(MQOO_OUTPUT,MQOO_INQUIRE,MQOO_FAIL_IF_QUIESCING) READA(NO) OBJNAME(AMQ.MQEXPLORER.6A62E5CC23150603) OBJTYPE(QUEUE) ASTATE(NONE) HSTATE(INACTIVE) OPENOPTS(MQOO_INPUT_EXCLUSIVE,MQOO_FAIL_IF_QUIESCING) READA(NO) AMQ8276I: Display Connection details. CONN(CCE5626A01E81423) EXTCONN(414D5143564E52443031202020202020) TYPE(*) PID(7276) TID(3) APPLDESC(IBM MQ Queued Pub/Sub Initiator) APPLTAG(es\IBM\MQ\bin64\amqzmuf0.exe) APPLTYPE(SYSTEM) ASTATE(NONE) CHANNEL( ) CLIENTID( ) CONNAME( ) CONNOPTS(MQCNO_FASTPATH_BINDING) USERID(prodMqTdh) UOWLOG( ) UOWSTDA( ) UOWSTTI( ) UOWLOGDA( ) UOWLOGTI( ) URTYPE(QMGR) EXTURID(XA_FORMATID[] XA_GTRID[] XA_BQUAL[]) QMURID(0.0) UOWSTATE(NONE) OBJNAME(VNRD01) OBJTYPE(QMGR) ASTATE(NONE) HSTATE(INACTIVE) OPENOPTS(MQOO_INQUIRE) READA(NO) AMQ8276I: Display Connection details. CONN(CCE5626A020B1523) EXTCONN(414D5143564E52443031202020202020) TYPE(*) PID(3040) TID(8) APPLDESC(IBM MQ Channel) APPLTAG(YarnCoarseGrainedExecutorBac) APPLTYPE(USER) ASTATE(NONE) CHANNEL(APP) CLIENTID( ) CONNAME(10.111.13.18) CONNOPTS(MQCNO_HANDLE_SHARE_BLOCK,MQCNO_SHARED_BINDING) USERID(prodMqTdh) UOWLOG( ) UOWSTDA( ) UOWSTTI( ) UOWLOGDA( ) UOWLOGTI( ) URTYPE(QMGR) EXTURID(XA_FORMATID[] XA_GTRID[] XA_BQUAL[]) QMURID(0.0) UOWSTATE(NONE) OBJNAME(VNRD01) OBJTYPE(QMGR) ASTATE(NONE) HSTATE(INACTIVE) OPENOPTS(MQOO_INQUIRE) READA(NO) OBJNAME(VN.SKD.PRD.IN) OBJTYPE(QUEUE) ASTATE(NONE) HSTATE(INACTIVE) OPENOPTS(MQOO_INPUT_SHARED,MQOO_BROWSE,MQOO_FAIL_IF_QUIESCING) READA(NO) AMQ8276I: Display Connection details. CONN(CCE5626A010D1523) EXTCONN(414D5143564E52443031202020202020) TYPE(*) PID(3040) TID(4) APPLDESC(IBM MQ Channel) APPLTAG(YarnCoarseGrainedExecutorBac) APPLTYPE(USER) ASTATE(NONE) CHANNEL(APP) CLIENTID( ) CONNAME(10.111.13.16) CONNOPTS(MQCNO_HANDLE_SHARE_BLOCK,MQCNO_SHARED_BINDING) USERID(prodMqTdh) UOWLOG( ) UOWSTDA( ) UOWSTTI( ) UOWLOGDA( ) UOWLOGTI( ) URTYPE(QMGR) EXTURID(XA_FORMATID[] XA_GTRID[] XA_BQUAL[]) QMURID(0.0) UOWSTATE(NONE) OBJNAME(VNRD01) OBJTYPE(QMGR) ASTATE(NONE) HSTATE(INACTIVE) OPENOPTS(MQOO_INQUIRE) READA(NO) OBJNAME(VN.PNR.PRD.IN) OBJTYPE(QUEUE) ASTATE(NONE) HSTATE(INACTIVE) OPENOPTS(MQOO_INPUT_SHARED,MQOO_BROWSE,MQOO_FAIL_IF_QUIESCING) READA(NO) AMQ8276I: Display Connection details. CONN(CCE5626A010E1523) EXTCONN(414D5143564E52443031202020202020) TYPE(*) PID(3040) TID(5) APPLDESC(IBM MQ Channel) APPLTAG(YarnCoarseGrainedExecutorBac) APPLTYPE(USER) ASTATE(NONE) CHANNEL(APP) CLIENTID( ) CONNAME(10.111.13.18) CONNOPTS(MQCNO_HANDLE_SHARE_BLOCK,MQCNO_SHARED_BINDING) USERID(prodMqTdh) UOWLOG( ) UOWSTDA( ) UOWSTTI( ) UOWLOGDA( ) UOWLOGTI( ) URTYPE(QMGR) EXTURID(XA_FORMATID[] XA_GTRID[] XA_BQUAL[]) QMURID(0.0) UOWSTATE(NONE) OBJNAME(VNRD01) OBJTYPE(QMGR) ASTATE(NONE) HSTATE(INACTIVE) OPENOPTS(MQOO_INQUIRE) READA(NO) OBJNAME(VN.TKT.PRD.IN) OBJTYPE(QUEUE) ASTATE(NONE) HSTATE(INACTIVE) OPENOPTS(MQOO_INPUT_SHARED,MQOO_BROWSE,MQOO_FAIL_IF_QUIESCING) READA(NO) AMQ8276I: Display Connection details. CONN(CCE5626A01EE1423) EXTCONN(414D5143564E52443031202020202020) TYPE(*) PID(7152) TID(30) APPLDESC(IBM MQ Resource Monitor Task) APPLTAG(es\IBM\MQ\bin64\amqzmuc0.exe) APPLTYPE(SYSTEM) ASTATE(NONE) CHANNEL( ) CLIENTID( ) CONNAME( ) CONNOPTS(MQCNO_FASTPATH_BINDING) USERID(prodMqTdh) UOWLOG( ) UOWSTDA( ) UOWSTTI( ) UOWLOGDA( ) UOWLOGTI( ) URTYPE(QMGR) EXTURID(XA_FORMATID[] XA_GTRID[] XA_BQUAL[]) QMURID(0.0) UOWSTATE(NONE) OBJNAME( ) OBJTYPE(TOPIC) ASTATE(NONE) HSTATE(INACTIVE) OPENOPTS(MQOO_OUTPUT,MQOO_FAIL_IF_QUIESCING) READA(NO) TOPICSTR($SYS/MQ/INFO/QMGR/VNRD01/Monitor/CPU/SystemSummary) OBJNAME( ) OBJTYPE(TOPIC) ASTATE(NONE) HSTATE(INACTIVE) OPENOPTS(MQOO_OUTPUT,MQOO_FAIL_IF_QUIESCING) READA(NO) TOPICSTR($SYS/MQ/INFO/QMGR/VNRD01/Monitor/CPU/QMgrSummary) OBJNAME( ) OBJTYPE(TOPIC) ASTATE(NONE) HSTATE(INACTIVE) OPENOPTS(MQOO_OUTPUT,MQOO_FAIL_IF_QUIESCING) READA(NO) TOPICSTR($SYS/MQ/INFO/QMGR/VNRD01/Monitor/DISK/SystemSummary) OBJNAME( ) OBJTYPE(TOPIC) ASTATE(NONE) HSTATE(INACTIVE) OPENOPTS(MQOO_OUTPUT,MQOO_FAIL_IF_QUIESCING) READA(NO) TOPICSTR($SYS/MQ/INFO/QMGR/VNRD01/Monitor/DISK/QMgrSummary) OBJNAME( ) OBJTYPE(TOPIC) ASTATE(NONE) HSTATE(INACTIVE) OPENOPTS(MQOO_OUTPUT,MQOO_FAIL_IF_QUIESCING) READA(NO) TOPICSTR($SYS/MQ/INFO/QMGR/VNRD01/Monitor/DISK/Log) OBJNAME( ) OBJTYPE(TOPIC) ASTATE(NONE) HSTATE(INACTIVE) OPENOPTS(MQOO_OUTPUT,MQOO_FAIL_IF_QUIESCING) READA(NO) TOPICSTR($SYS/MQ/INFO/QMGR/VNRD01/Monitor/STATMQI/CONNDISC) OBJNAME( ) OBJTYPE(TOPIC) ASTATE(NONE) HSTATE(INACTIVE) OPENOPTS(MQOO_OUTPUT,MQOO_FAIL_IF_QUIESCING) READA(NO) TOPICSTR($SYS/MQ/INFO/QMGR/VNRD01/Monitor/STATMQI/OPENCLOSE) OBJNAME( ) OBJTYPE(TOPIC) ASTATE(NONE) HSTATE(INACTIVE) OPENOPTS(MQOO_OUTPUT,MQOO_FAIL_IF_QUIESCING) READA(NO) TOPICSTR($SYS/MQ/INFO/QMGR/VNRD01/Monitor/STATMQI/INQSET) OBJNAME( ) OBJTYPE(TOPIC) ASTATE(NONE) HSTATE(INACTIVE) OPENOPTS(MQOO_OUTPUT,MQOO_FAIL_IF_QUIESCING) READA(NO) TOPICSTR($SYS/MQ/INFO/QMGR/VNRD01/Monitor/STATMQI/PUT) OBJNAME( ) OBJTYPE(TOPIC) ASTATE(NONE) HSTATE(INACTIVE) OPENOPTS(MQOO_OUTPUT,MQOO_FAIL_IF_QUIESCING) READA(NO) TOPICSTR($SYS/MQ/INFO/QMGR/VNRD01/Monitor/STATMQI/GET) OBJNAME( ) OBJTYPE(TOPIC) ASTATE(NONE) HSTATE(INACTIVE) OPENOPTS(MQOO_OUTPUT,MQOO_FAIL_IF_QUIESCING) READA(NO) TOPICSTR($SYS/MQ/INFO/QMGR/VNRD01/Monitor/STATMQI/SYNCPOINT) OBJNAME( ) OBJTYPE(TOPIC) ASTATE(NONE) HSTATE(INACTIVE) OPENOPTS(MQOO_OUTPUT,MQOO_FAIL_IF_QUIESCING) READA(NO) TOPICSTR($SYS/MQ/INFO/QMGR/VNRD01/Monitor/STATMQI/SUBSCRIBE) OBJNAME( ) OBJTYPE(TOPIC) ASTATE(NONE) HSTATE(INACTIVE) OPENOPTS(MQOO_OUTPUT,MQOO_FAIL_IF_QUIESCING) READA(NO) TOPICSTR($SYS/MQ/INFO/QMGR/VNRD01/Monitor/STATMQI/PUBLISH) AMQ8276I: Display Connection details. CONN(CCE5626A010F1523) EXTCONN(414D5143564E52443031202020202020) TYPE(*) PID(3040) TID(6) APPLDESC(IBM MQ Channel) APPLTAG(YarnCoarseGrainedExecutorBac) APPLTYPE(USER) ASTATE(NONE) CHANNEL(APP) CLIENTID( ) CONNAME(10.111.13.18) CONNOPTS(MQCNO_HANDLE_SHARE_BLOCK,MQCNO_SHARED_BINDING) USERID(prodMqTdh) UOWLOG( ) UOWSTDA( ) UOWSTTI( ) UOWLOGDA( ) UOWLOGTI( ) URTYPE(QMGR) EXTURID(XA_FORMATID[] XA_GTRID[] XA_BQUAL[]) QMURID(0.0) UOWSTATE(NONE) OBJNAME(VNRD01) OBJTYPE(QMGR) ASTATE(NONE) HSTATE(INACTIVE) OPENOPTS(MQOO_INQUIRE) READA(NO) OBJNAME(VN.CMP.PRD.IN) OBJTYPE(QUEUE) ASTATE(NONE) HSTATE(INACTIVE) OPENOPTS(MQOO_INPUT_SHARED,MQOO_BROWSE,MQOO_FAIL_IF_QUIESCING) READA(NO) AMQ8276I: Display Connection details. CONN(CCE5626A02101523) EXTCONN(414D5143564E52443031202020202020) TYPE(*) PID(3040) TID(9) APPLDESC(IBM MQ Channel) APPLTAG(YarnCoarseGrainedExecutorBac) APPLTYPE(USER) ASTATE(NONE) CHANNEL(APP) CLIENTID( ) CONNAME(10.111.13.17) CONNOPTS(MQCNO_HANDLE_SHARE_BLOCK,MQCNO_SHARED_BINDING) USERID(prodMqTdh) UOWLOG( ) UOWSTDA( ) UOWSTTI( ) UOWLOGDA( ) UOWLOGTI( ) URTYPE(QMGR) EXTURID(XA_FORMATID[] XA_GTRID[] XA_BQUAL[]) QMURID(0.0) UOWSTATE(NONE) OBJNAME(VNRD01) OBJTYPE(QMGR) ASTATE(NONE) HSTATE(INACTIVE) OPENOPTS(MQOO_INQUIRE) READA(NO) OBJNAME(VN.CMB.PRD.IN) OBJTYPE(QUEUE) ASTATE(NONE) HSTATE(INACTIVE) OPENOPTS(MQOO_INPUT_SHARED,MQOO_BROWSE,MQOO_FAIL_IF_QUIESCING) READA(NO) AMQ8276I: Display Connection details. CONN(CCE5626A01EF1423) EXTCONN(414D5143564E52443031202020202020) TYPE(*) PID(7276) TID(6) APPLDESC(IBM MQ Distributed Pub/Sub Controller) APPLTAG(es\IBM\MQ\bin64\amqzmuf0.exe) APPLTYPE(SYSTEM) ASTATE(NONE) CHANNEL( ) CLIENTID( ) CONNAME( ) CONNOPTS(MQCNO_FASTPATH_BINDING) USERID(prodMqTdh) UOWLOG( ) UOWSTDA( ) UOWSTTI( ) UOWLOGDA( ) UOWLOGTI( ) URTYPE(QMGR) EXTURID(XA_FORMATID[] XA_GTRID[] XA_BQUAL[]) QMURID(0.0) UOWSTATE(NONE) OBJNAME(VNRD01) OBJTYPE(QMGR) ASTATE(NONE) HSTATE(INACTIVE) OPENOPTS(MQOO_INQUIRE) READA(NO) AMQ8276I: Display Connection details. CONN(CCE5626A01F01423) EXTCONN(414D5143564E52443031202020202020) TYPE(*) PID(7276) TID(8) APPLDESC(IBM MQ Distributed Pub/Sub Command Task) APPLTAG(es\IBM\MQ\bin64\amqzmuf0.exe) APPLTYPE(SYSTEM) ASTATE(NONE) CHANNEL( ) CLIENTID( ) CONNAME( ) CONNOPTS(MQCNO_FASTPATH_BINDING) USERID(prodMqTdh) UOWLOG( ) UOWSTDA(2026-07-24) UOWSTTI(11.10.52) UOWLOGDA( ) UOWLOGTI( ) URTYPE(QMGR) EXTURID(XA_FORMATID[] XA_GTRID[] XA_BQUAL[]) QMURID(0.8192) UOWSTATE(ACTIVE) OBJNAME(SYSTEM.INTER.QMGR.CONTROL) OBJTYPE(QUEUE) ASTATE(NONE) HSTATE(ACTIVE) OPENOPTS(MQOO_INPUT_SHARED,MQOO_SAVE_ALL_CONTEXT,MQOO_FAIL_IF_QUIESCING) READA(NO)
A8: DISPLAY CHANNEL(*) ALL | B8: Đã chạy | C8: display channel(*) all 12 : display channel(*) all AMQ8414I: Display Channel details. CHANNEL(1A.CLUSP_VNRD01) CHLTYPE(RCVR) ALTDATE(2026-03-30) ALTTIME(16.34.58) BATCHSZ(100) CERTLABL( ) COMPHDR(NONE) COMPMSG(ZLIBFAST,NONE) DESCR( ) HBINT(20) KAINT(AUTO) MAXMSGL(4194304) MCAUSER( ) MONCHL(QMGR) MRDATA( ) MREXIT( ) MRRTY(10) MRTMR(1000) MSGDATA( ) MSGEXIT( ) NPMSPEED(FAST) PUTAUT(DEF) RCVDATA( ) RCVEXIT( ) RESETSEQ(NO) SCYDATA( ) SCYEXIT( ) SENDDATA( ) SENDEXIT( ) SEQWRAP(999999999) SSLCAUTH(REQUIRED) SSLCIPH( ) SSLPEER( ) STATCHL(QMGR) TRPTYPE(TCP) USEDLQ(YES) AMQ8414I: Display Channel details. CHANNEL(APP) CHLTYPE(SVRCONN) ALTDATE(2026-03-16) ALTTIME(17.21.52) CERTLABL( ) COMPHDR(NONE) COMPMSG(NONE) DESCR( ) DISCINT(0) HBINT(20) KAINT(AUTO) MAXINST(999999999) MAXINSTC(999999999) MAXMSGL(4194304) MCAUSER(prodMqTdh) MONCHL(QMGR) RCVDATA( ) RCVEXIT( ) SCYDATA( ) SCYEXIT( ) SENDDATA( ) SENDEXIT( ) SHARECNV(10) SSLCAUTH(REQUIRED) SSLCIPH( ) SSLPEER( ) TRPTYPE(TCP) AMQ8414I: Display Channel details. CHANNEL(SYSTEM.AUTO.RECEIVER) CHLTYPE(RCVR) ALTDATE(2026-03-16) ALTTIME(17.03.51) BATCHSZ(50) CERTLABL( ) COMPHDR(NONE) COMPMSG(NONE) DESCR(Auto-defined by) HBINT(300) KAINT(AUTO) MAXMSGL(4194304) MCAUSER( ) MONCHL(QMGR) MRDATA( ) MREXIT( ) MRRTY(10) MRTMR(1000) MSGDATA( ) MSGEXIT( ) NPMSPEED(FAST) PUTAUT(DEF) RCVDATA( ) RCVEXIT( ) RESETSEQ(NO) SCYDATA( ) SCYEXIT( ) SENDDATA( ) SENDEXIT( ) SEQWRAP(999999999) SSLCAUTH(REQUIRED) SSLCIPH( ) SSLPEER( ) STATCHL(QMGR) TRPTYPE(TCP) USEDLQ(YES) AMQ8414I: Display Channel details. CHANNEL(SYSTEM.AUTO.SVRCONN) CHLTYPE(SVRCONN) ALTDATE(2026-03-16) ALTTIME(17.03.51) CERTLABL( ) COMPHDR(NONE) COMPMSG(NONE) DESCR(Auto-defined by) DISCINT(0) HBINT(300) KAINT(AUTO) MAXINST(999999999) MAXINSTC(999999999) MAXMSGL(4194304) MCAUSER( ) MONCHL(QMGR) RCVDATA( ) RCVEXIT( ) SCYDATA( ) SCYEXIT( ) SENDDATA( ) SENDEXIT( ) SHARECNV(10) SSLCAUTH(REQUIRED) SSLCIPH( ) SSLPEER( ) TRPTYPE(TCP) AMQ8414I: Display Channel details. CHANNEL(SYSTEM.DEF.AMQP) CHLTYPE(AMQP) ALTDATE(2026-03-16) ALTTIME(17.03.52) CERTLABL( ) DESCR( ) AMQPKA(AUTO) LOCLADDR( ) MAXINST(999999999) MAXMSGL(4194304) MCAUSER( ) PORT(5672) SSLCAUTH(REQUIRED) SSLCIPH( ) SSLPEER( ) TPROOT(SYSTEM.BASE.TOPIC) USECLTID(NO) AMQ8414I: Display Channel details. CHANNEL(SYSTEM.DEF.CLUSRCVR) CHLTYPE(CLUSRCVR) ALTDATE(2026-03-16) ALTTIME(17.03.51) BATCHHB(0) BATCHINT(0) BATCHLIM(5000) BATCHSZ(50) CERTLABL( ) CLUSNL( ) CLUSTER( ) CLWLPRTY(0) CLWLRANK(0) CLWLWGHT(50) COMPHDR(NONE) COMPMSG(NONE) CONNAME( ) CONVERT(NO) DESCR( ) DISCINT(6000) HBINT(300) KAINT(AUTO) LOCLADDR( ) LONGRTY(999999999) LONGTMR(1200) MAXMSGL(4194304) MCANAME( ) MCATYPE(THREAD) MCAUSER( ) MODENAME( ) MONCHL(QMGR) MRDATA( ) MREXIT( ) MRRTY(10) MRTMR(1000) MSGDATA( ) MSGEXIT( ) NETPRTY(0) NPMSPEED(FAST) PROPCTL(COMPAT) PUTAUT(DEF) RCVDATA( ) RCVEXIT( ) RESETSEQ(NO) SCYDATA( ) SCYEXIT( ) SENDDATA( ) SENDEXIT( ) SEQWRAP(999999999) SHORTRTY(10) SHORTTMR(60) SSLCAUTH(REQUIRED) SSLCIPH( ) SSLPEER( ) STATCHL(QMGR) TPNAME( ) TRPTYPE(TCP) USEDLQ(YES) AMQ8414I: Display Channel details. CHANNEL(SYSTEM.DEF.CLUSSDR) CHLTYPE(CLUSSDR) ALTDATE(2026-03-16) ALTTIME(17.03.50) BATCHHB(0) BATCHINT(0) BATCHLIM(5000) BATCHSZ(50) CLUSNL( ) CLUSTER( ) CLWLPRTY(0) CLWLRANK(0) CLWLWGHT(50) COMPHDR(NONE) COMPMSG(NONE) CONNAME( ) CONVERT(NO) DESCR( ) DISCINT(6000) HBINT(300) KAINT(AUTO) LOCLADDR( ) LONGRTY(999999999) LONGTMR(1200) MAXMSGL(4194304) MCANAME( ) MCATYPE(THREAD) MCAUSER( ) MODENAME( ) MONCHL(QMGR) MSGDATA( ) MSGEXIT( ) NPMSPEED(FAST) PASSWORD( ) PROPCTL(COMPAT) RCVDATA( ) RCVEXIT( ) RESETSEQ(NO) SCYDATA( ) SCYEXIT( ) SENDDATA( ) SENDEXIT( ) SEQWRAP(999999999) SHORTRTY(10) SHORTTMR(60) SSLCIPH( ) SSLPEER( ) STATCHL(QMGR) TPNAME( ) TRPTYPE(TCP) USEDLQ(YES) USERID( ) AMQ8414I: Display Channel details. CHANNEL(SYSTEM.DEF.RECEIVER) CHLTYPE(RCVR) ALTDATE(2026-03-16) ALTTIME(17.03.50) BATCHSZ(50) CERTLABL( ) COMPHDR(NONE) COMPMSG(NONE) DESCR( ) HBINT(300) KAINT(AUTO) MAXMSGL(4194304) MCAUSER( ) MONCHL(QMGR) MRDATA( ) MREXIT( ) MRRTY(10) MRTMR(1000) MSGDATA( ) MSGEXIT( ) NPMSPEED(FAST) PUTAUT(DEF) RCVDATA( ) RCVEXIT( ) RESETSEQ(NO) SCYDATA( ) SCYEXIT( ) SENDDATA( ) SENDEXIT( ) SEQWRAP(999999999) SSLCAUTH(REQUIRED) SSLCIPH( ) SSLPEER( ) STATCHL(QMGR) TRPTYPE(TCP) USEDLQ(YES) AMQ8414I: Display Channel details. CHANNEL(SYSTEM.DEF.REQUESTER) CHLTYPE(RQSTR) ALTDATE(2026-03-16) ALTTIME(17.03.50) BATCHSZ(50) CERTLABL( ) COMPHDR(NONE) COMPMSG(NONE) CONNAME( ) DESCR( ) HBINT(300) KAINT(AUTO) LOCLADDR( ) MAXMSGL(4194304) MCANAME( ) MCATYPE(PROCESS) MCAUSER( ) MODENAME( ) MONCHL(QMGR) MRDATA( ) MREXIT( ) MRRTY(10) MRTMR(1000) MSGDATA( ) MSGEXIT( ) NPMSPEED(FAST) PASSWORD( ) PUTAUT(DEF) RCVDATA( ) RCVEXIT( ) RESETSEQ(NO) SCYDATA( ) SCYEXIT( ) SENDDATA( ) SENDEXIT( ) SEQWRAP(999999999) SSLCAUTH(REQUIRED) SSLCIPH( ) SSLPEER( ) STATCHL(QMGR) TPNAME( ) TRPTYPE(TCP) USEDLQ(YES) USERID( ) AMQ8414I: Display Channel details. CHANNEL(SYSTEM.DEF.SENDER) CHLTYPE(SDR) ALTDATE(2026-03-16) ALTTIME(17.03.50) BATCHHB(0) BATCHINT(0) BATCHLIM(5000) BATCHSZ(50) CERTLABL( ) COMPHDR(NONE) COMPMSG(NONE) CONNAME( ) CONVERT(NO) DESCR( ) DISCINT(6000) HBINT(300) KAINT(AUTO) LOCLADDR( ) LONGRTY(999999999) LONGTMR(1200) MAXMSGL(4194304) MCANAME( ) MCATYPE(PROCESS) MCAUSER( ) MODENAME( ) MONCHL(QMGR) MSGDATA( ) MSGEXIT( ) NPMSPEED(FAST) PASSWORD( ) PROPCTL(COMPAT) RCVDATA( ) RCVEXIT( ) RESETSEQ(NO) SCYDATA( ) SCYEXIT( ) SENDDATA( ) SENDEXIT( ) SEQWRAP(999999999) SHORTRTY(10) SHORTTMR(60) SSLCIPH( ) SSLPEER( ) STATCHL(QMGR) TPNAME( ) TRPTYPE(TCP) USEDLQ(YES) USERID( ) XMITQ( ) AMQ8414I: Display Channel details. CHANNEL(SYSTEM.DEF.SERVER) CHLTYPE(SVR) ALTDATE(2026-03-16) ALTTIME(17.03.50) BATCHHB(0) BATCHINT(0) BATCHLIM(5000) BATCHSZ(50) CERTLABL( ) COMPHDR(NONE) COMPMSG(NONE) CONNAME( ) CONVERT(NO) DESCR( ) DISCINT(6000) HBINT(300) KAINT(AUTO) LOCLADDR( ) LONGRTY(999999999) LONGTMR(1200) MAXMSGL(4194304) MCANAME( ) MCATYPE(PROCESS) MCAUSER( ) MODENAME( ) MONCHL(QMGR) MSGDATA( ) MSGEXIT( ) NPMSPEED(FAST) PASSWORD( ) PROPCTL(COMPAT) RCVDATA( ) RCVEXIT( ) RESETSEQ(NO) SCYDATA( ) SCYEXIT( ) SENDDATA( ) SENDEXIT( ) SEQWRAP(999999999) SHORTRTY(10) SHORTTMR(60) SSLCAUTH(REQUIRED) SSLCIPH( ) SSLPEER( ) STATCHL(QMGR) TPNAME( ) TRPTYPE(TCP) USEDLQ(YES) USERID( ) XMITQ( ) AMQ8414I: Display Channel details. CHANNEL(SYSTEM.DEF.SVRCONN) CHLTYPE(SVRCONN) ALTDATE(2026-03-16) ALTTIME(17.03.50) CERTLABL( ) COMPHDR(NONE) COMPMSG(NONE) DESCR( ) DISCINT(0) HBINT(300) KAINT(AUTO) MAXINST(999999999) MAXINSTC(999999999) MAXMSGL(4194304) MCAUSER( ) MONCHL(QMGR) RCVDATA( ) RCVEXIT( ) SCYDATA( ) SCYEXIT( ) SENDDATA( ) SENDEXIT( ) SHARECNV(10) SSLCAUTH(REQUIRED) SSLCIPH( ) SSLPEER( ) TRPTYPE(TCP) AMQ8414I: Display Channel details. CHANNEL(SYSTEM.DEF.CLNTCONN) CHLTYPE(CLNTCONN) AFFINITY(PREFERRED) ALTDATE(2026-03-16) ALTTIME(17.03.50) CERTLABL( ) CLNTWGHT(0) COMPHDR(NONE) COMPMSG(NONE) CONNAME( ) DEFRECON(NO) DESCR( ) HBINT(300) KAINT(AUTO) LOCLADDR( ) MAXMSGL(4194304) MODENAME( ) PASSWORD( ) QMNAME( ) RCVDATA( ) RCVEXIT( ) SCYDATA( ) SCYEXIT( ) SENDDATA( ) SENDEXIT( ) SHARECNV(10) SSLCIPH( ) SSLPEER( ) TPNAME( ) TRPTYPE(TCP) USERID( )
